Workbook

Sheet 매핑
A1: 기존 | B1: 푸디스트_코드 | C1: 푸디스트 | F1: 현그푸_코드 | G1: 현그푸
A2: 갓 | D2: =VLOOKUP(B2,푸디스트!A:D,3,FALSE) -> #N/A | E2: =VLOOKUP(B2,푸디스트!A:D,4,FALSE) -> #N/A | H2: =VLOOKUP(F2,현그푸!A:D,3,FALSE) -> #N/A | I2: =VLOOKUP(F2,현그푸!A:D,4,FALSE) -> #N/A
A3: 쑥 | D3: =VLOOKUP(B3,푸디스트!A:D,3,FALSE) -> #N/A | E3: =VLOOKUP(B3,푸디스트!A:D,4,FALSE) -> #N/A | H3: =VLOOKUP(F3,현그푸!A:D,3,FALSE) -> #N/A | I3: =VLOOKUP(F3,현그푸!A:D,4,FALSE) -> #N/A
A4: 쑥갓 | B4: F100835 | C4: 쑥갓(국내산) | D4: =VLOOKUP(B4,푸디스트!A:D,3,FALSE) -> KG/상 | E4: =VLOOKUP(B4,푸디스트!A:D,4,FALSE) -> 6760 | H4: =VLOOKUP(F4,현그푸!A:D,3,FALSE) -> #N/A | I4: =VLOOKUP(F4,현그푸!A:D,4,FALSE) -> #N/A
A5: 애느타리버섯 | B5: F314300 | C5: 애느타리버섯(국내산) | D5: =VLOOKUP(B5,푸디스트!A:D,3,FALSE) -> 1KG | E5: =VLOOKUP(B5,푸디스트!A:D,4,FALSE) -> 5340 | H5: =VLOOKUP(F5,현그푸!A:D,3,FALSE) -> #N/A | I5: =VLOOKUP(F5,현그푸!A:D,4,FALSE) -> #N/A
A6: 느타리버섯 | B6: F134414 | C6: 느타리버섯(국내산)특 | D6: =VLOOKUP(B6,푸디스트!A:D,3,FALSE) -> KG/특/찹찹이 | E6: =VLOOKUP(B6,푸디스트!A:D,4,FALSE) -> 11470 | H6: =VLOOKUP(F6,현그푸!A:D,3,FALSE) -> #N/A | I6: =VLOOKUP(F6,현그푸!A:D,4,FALSE) -> #N/A
A7: 고구마순(줄기) | B7: F268247 | C7: 데친고구마순(중국산) | D7: =VLOOKUP(B7,푸디스트!A:D,3,FALSE) -> 1KG/EA | E7: =VLOOKUP(B7,푸디스트!A:D,4,FALSE) -> 4210 | H7: =VLOOKUP(F7,현그푸!A:D,3,FALSE) -> #N/A | I7: =VLOOKUP(F7,현그푸!A:D,4,FALSE) -> #N/A
A8: 월계수잎 | B8: F119932 | C8: 월계수잎(은진) | D8: =VLOOKUP(B8,푸디스트!A:D,3,FALSE) -> 230G/건조/국내소분 | E8: =VLOOKUP(B8,푸디스트!A:D,4,FALSE) -> 7250 | H8: =VLOOKUP(F8,현그푸!A:D,3,FALSE) -> #N/A | I8: =VLOOKUP(F8,현그푸!A:D,4,FALSE) -> #N/A
A9: 전분가루 | B9: F268394 | C9: 감자전분가루(뚜레반) | D9: =VLOOKUP(B9,푸디스트!A:D,3,FALSE) -> 3KG/수입산 | E9: =VLOOKUP(B9,푸디스트!A:D,4,FALSE) -> 15110 | H9: =VLOOKUP(F9,현그푸!A:D,3,FALSE) -> #N/A | I9: =VLOOKUP(F9,현그푸!A:D,4,FALSE) -> #N/A
A10: 새우젓 | B10: F349836 | C10: 새우젓(씨엔에프)(면세) | D10: =VLOOKUP(B10,푸디스트!A:D,3,FALSE) -> 1KG/베트남산/씨엔에프(키원글로벌) | E10: =VLOOKUP(B10,푸디스트!A:D,4,FALSE) -> 4130 | H10: =VLOOKUP(F10,현그푸!A:D,3,FALSE) -> #N/A | I10: =VLOOKUP(F10,현그푸!A:D,4,FALSE) -> #N/A
A11: 스테이크소스 | B11: F119066 | C11: 스테이크소스(대상) | D11: =VLOOKUP(B11,푸디스트!A:D,3,FALSE) -> 3.3KG/스테이크/대상 | E11: =VLOOKUP(B11,푸디스트!A:D,4,FALSE) -> 12460 | H11: =VLOOKUP(F11,현그푸!A:D,3,FALSE) -> #N/A | I11: =VLOOKUP(F11,현그푸!A:D,4,FALSE) -> #N/A
A12: 다시마육수 | D12: =VLOOKUP(B12,푸디스트!A:D,3,FALSE) -> #N/A | E12: =VLOOKUP(B12,푸디스트!A:D,4,FALSE) -> #N/A | H12: =VLOOKUP(F12,현그푸!A:D,3,FALSE) -> #N/A | I12: =VLOOKUP(F12,현그푸!A:D,4,FALSE) -> #N/A
A13: 목이버섯 | D13: =VLOOKUP(B13,푸디스트!A:D,3,FALSE) -> #N/A | E13: =VLOOKUP(B13,푸디스트!A:D,4,FALSE) -> #N/A | F13: 1456954 | G13: (C)목이버섯(상품,냉장,데친(건),중국) | H13: =VLOOKUP(F13,현그푸!A:D,3,FALSE) -> 500g | I13: =VLOOKUP(F13,현그푸!A:D,4,FALSE) -> 5460
A14: 당근 | B14: F100467 | C14: 세척당근(국내산) | D14: =VLOOKUP(B14,푸디스트!A:D,3,FALSE) -> KG/개당200G이상 | E14: =VLOOKUP(B14,푸디스트!A:D,4,FALSE) -> 3180 | H14: =VLOOKUP(F14,현그푸!A:D,3,FALSE) -> #N/A | I14: =VLOOKUP(F14,현그푸!A:D,4,FALSE) -> #N/A
A15: 어묵 | B15: F112095 | C15: 어묵(푸치오사카나아쯔아게/모노링크) | D15: =VLOOKUP(B15,푸디스트!A:D,3,FALSE) -> 500G | E15: =VLOOKUP(B15,푸디스트!A:D,4,FALSE) -> 7040 | H15: =VLOOKUP(F15,현그푸!A:D,3,FALSE) -> #N/A | I15: =VLOOKUP(F15,현그푸!A:D,4,FALSE) -> #N/A
A16: 배추 | B16: F100703 | C16: 깐배추(국내산)/상 | D16: =VLOOKUP(B16,푸디스트!A:D,3,FALSE) -> KG/상/깐것 | E16: =VLOOKUP(B16,푸디스트!A:D,4,FALSE) -> 2390 | H16: =VLOOKUP(F16,현그푸!A:D,3,FALSE) -> #N/A | I16: =VLOOKUP(F16,현그푸!A:D,4,FALSE) -> #N/A
A17: 참깨(간것) | B17: F329350 | C17: 볶음참깨갈음(청학) | D17: =VLOOKUP(B17,푸디스트!A:D,3,FALSE) -> 1KG | E17: =VLOOKUP(B17,푸디스트!A:D,4,FALSE) -> 8630 | H17: =VLOOKUP(F17,현그푸!A:D,3,FALSE) -> #N/A | I17: =VLOOKUP(F17,현그푸!A:D,4,FALSE) -> #N/A
A18: 마늘(다진것) | B18: F101046 | C18: 다진마늘(국내산)/상(꼭지포함) | D18: =VLOOKUP(B18,푸디스트!A:D,3,FALSE) -> EA/1KG/상/꼭지포함 | E18: =VLOOKUP(B18,푸디스트!A:D,4,FALSE) -> 8930 | H18: =VLOOKUP(F18,현그푸!A:D,3,FALSE) -> #N/A | I18: =VLOOKUP(F18,현그푸!A:D,4,FALSE) -> #N/A
A19: 멸치(분말) | B19: F357905 | C19: (식자재왕)멸치육수분말_1kg_F2 | D19: =VLOOKUP(B19,푸디스트!A:D,3,FALSE) -> 1kg/10/삼아벤처 | E19: =VLOOKUP(B19,푸디스트!A:D,4,FALSE) -> 7450 | H19: =VLOOKUP(F19,현그푸!A:D,3,FALSE) -> #N/A | I19: =VLOOKUP(F19,현그푸!A:D,4,FALSE) -> #N/A
A20: 게맛살 | B20: F305470 | C20: (식자재왕)게맛살_1kg | D20: =VLOOKUP(B20,푸디스트!A:D,3,FALSE) -> 1KG{29G(19cm)*35개}/한성기업㈜강남영업소 | E20: =VLOOKUP(B20,푸디스트!A:D,4,FALSE) -> 3180 | H20: =VLOOKUP(F20,현그푸!A:D,3,FALSE) -> #N/A | I20: =VLOOKUP(F20,현그푸!A:D,4,FALSE) -> #N/A
A21: 물엿 | B21: F120424 | C21: 물엿(백/강남) | D21: =VLOOKUP(B21,푸디스트!A:D,3,FALSE) -> 5KG | E21: =VLOOKUP(B21,푸디스트!A:D,4,FALSE) -> 14420 | H21: =VLOOKUP(F21,현그푸!A:D,3,FALSE) -> #N/A | I21: =VLOOKUP(F21,현그푸!A:D,4,FALSE) -> #N/A
A22: 생강소스 | D22: =VLOOKUP(B22,푸디스트!A:D,3,FALSE) -> #N/A | E22: =VLOOKUP(B22,푸디스트!A:D,4,FALSE) -> #N/A | H22: =VLOOKUP(F22,현그푸!A:D,3,FALSE) -> #N/A | I22: =VLOOKUP(F22,현그푸!A:D,4,FALSE) -> #N/A
A23: 치킨스톡 | B23: F335170 | C23: 치킨스톡(이엔) | D23: =VLOOKUP(B23,푸디스트!A:D,3,FALSE) -> 2.1kg | E23: =VLOOKUP(B23,푸디스트!A:D,4,FALSE) -> 17310 | H23: =VLOOKUP(F23,현그푸!A:D,3,FALSE) -> #N/A | I23: =VLOOKUP(F23,현그푸!A:D,4,FALSE) -> #N/A
A24: 유부 | B24: F113078 | C24: 유부(CJ씨푸드) | D24: =VLOOKUP(B24,푸디스트!A:D,3,FALSE) -> 300G/냉동 | E24: =VLOOKUP(B24,푸디스트!A:D,4,FALSE) -> 3990 | H24: =VLOOKUP(F24,현그푸!A:D,3,FALSE) -> #N/A | I24: =VLOOKUP(F24,현그푸!A:D,4,FALSE) -> #N/A
A25: 버터 | B25: F113814 | C25: 홈버터(무염)롯데푸드 | D25: =VLOOKUP(B25,푸디스트!A:D,3,FALSE) -> 450g/무염버터/롯데푸드㈜ | E25: =VLOOKUP(B25,푸디스트!A:D,4,FALSE) -> 8230 | H25: =VLOOKUP(F25,현그푸!A:D,3,FALSE) -> #N/A | I25: =VLOOKUP(F25,현그푸!A:D,4,FALSE) -> #N/A
A26: 무말랭이 | B26: F101926 | C26: 건무말랭이(중국산) | D26: =VLOOKUP(B26,푸디스트!A:D,3,FALSE) -> 1kg | E26: =VLOOKUP(B26,푸디스트!A:D,4,FALSE) -> 6870 | H26: =VLOOKUP(F26,현그푸!A:D,3,FALSE) -> #N/A | I26: =VLOOKUP(F26,현그푸!A:D,4,FALSE) -> #N/A
A27: 밀가루 | B27: F166982 | C27: 밀가루(중력/큐원) | D27: =VLOOKUP(B27,푸디스트!A:D,3,FALSE) -> 1KG/㈜삼양사 | E27: =VLOOKUP(B27,푸디스트!A:D,4,FALSE) -> 1830 | H27: =VLOOKUP(F27,현그푸!A:D,3,FALSE) -> #N/A | I27: =VLOOKUP(F27,현그푸!A:D,4,FALSE) -> #N/A
A28: 땅콩 | B28: F247521 | C28: 깐땅콩(중국산) | D28: =VLOOKUP(B28,푸디스트!A:D,3,FALSE) -> 500G/볶음/껍질없음/반쪼갬 | E28: =VLOOKUP(B28,푸디스트!A:D,4,FALSE) -> 4980 | H28: =VLOOKUP(F28,현그푸!A:D,3,FALSE) -> #N/A | I28: =VLOOKUP(F28,현그푸!A:D,4,FALSE) -> #N/A
A29: 고추장 | B29: F322796 | C29: (식자재왕)매콤한_태양초_고추장3kg_면세 | D29: =VLOOKUP(B29,푸디스트!A:D,3,FALSE) -> 3KG | E29: =VLOOKUP(B29,푸디스트!A:D,4,FALSE) -> 7180
A30: 된장 | B30: F322734 | C30: (식자재왕)된장_6.5kg | D30: =VLOOKUP(B30,푸디스트!A:D,3,FALSE) -> 6.5kg/2 | E30: =VLOOKUP(B30,푸디스트!A:D,4,FALSE) -> 13550 | H30: =VLOOKUP(F30,현그푸!A:D,3,FALSE) -> #N/A | I30: =VLOOKUP(F30,현그푸!A:D,4,FALSE) -> #N/A
A31: 매실농축액 | B31: F293155 | C31: [WB]매실농축액(참다음_6배수)1.5L | D31: =VLOOKUP(B31,푸디스트!A:D,3,FALSE) -> 1.5L/8ea*1box | E31: =VLOOKUP(B31,푸디스트!A:D,4,FALSE) -> 5220 | H31: =VLOOKUP(F31,현그푸!A:D,3,FALSE) -> #N/A | I31: =VLOOKUP(F31,현그푸!A:D,4,FALSE) -> #N/A
A32: 깨소금 | B32: F118699 | C32: 깨소금(신송)/센터 | D32: =VLOOKUP(B32,푸디스트!A:D,3,FALSE) -> 350G/팩(비닐) | E32: =VLOOKUP(B32,푸디스트!A:D,4,FALSE) -> 4950 | H32: =VLOOKUP(F32,현그푸!A:D,3,FALSE) -> #N/A | I32: =VLOOKUP(F32,현그푸!A:D,4,FALSE) -> #N/A
A33: 냉동얼갈이배추 | B33: F353050 | C33: [행사]냉동얼갈이(중국산) | D33: =VLOOKUP(B33,푸디스트!A:D,3,FALSE) -> [가열후사용]1KG/EA/3~5CM절단 | E33: =VLOOKUP(B33,푸디스트!A:D,4,FALSE) -> 1880 | H33: =VLOOKUP(F33,현그푸!A:D,3,FALSE) -> #N/A | I33: =VLOOKUP(F33,현그푸!A:D,4,FALSE) -> #N/A
A34: 맛간장 | B34: F322263 | C34: 맛간장(샘표)1.7L | D34: =VLOOKUP(B34,푸디스트!A:D,3,FALSE) -> 1.7L/조림/볶음용/용기(플라스틱) | E34: =VLOOKUP(B34,푸디스트!A:D,4,FALSE) -> 14300 | H34: =VLOOKUP(F34,현그푸!A:D,3,FALSE) -> #N/A | I34: =VLOOKUP(F34,현그푸!A:D,4,FALSE) -> #N/A
A35: 수제비(완제품) | B35: F250339 | C35: 수제비(동성) | D35: =VLOOKUP(B35,푸디스트!A:D,3,FALSE) -> 1KG | E35: =VLOOKUP(B35,푸디스트!A:D,4,FALSE) -> 3230 | H35: =VLOOKUP(F35,현그푸!A:D,3,FALSE) -> #N/A | I35: =VLOOKUP(F35,현그푸!A:D,4,FALSE) -> #N/A
A36: 애호박(냉동) | B36: F243715 | C36: 냉동애호박1/4컷(중국산) | D36: =VLOOKUP(B36,푸디스트!A:D,3,FALSE) -> [가열 후 사용]1KG/1/4컷 | E36: =VLOOKUP(B36,푸디스트!A:D,4,FALSE) -> 2420 | H36: =VLOOKUP(F36,현그푸!A:D,3,FALSE) -> #N/A | I36: =VLOOKUP(F36,현그푸!A:D,4,FALSE) -> #N/A
A37: 블랙올리브 | B37: F123155 | C37: 리치스블랙올리브(동서) | D37: =VLOOKUP(B37,푸디스트!A:D,3,FALSE) -> 3KG/슬라이스/㈜동서 | E37: =VLOOKUP(B37,푸디스트!A:D,4,FALSE) -> 14560 | H37: =VLOOKUP(F37,현그푸!A:D,3,FALSE) -> #N/A | I37: =VLOOKUP(F37,현그푸!A:D,4,FALSE) -> #N/A
A38: 맛술 | B38: F326281 | C38: (식자재왕)맛술_1.75L | D38: =VLOOKUP(B38,푸디스트!A:D,3,FALSE) -> 1.75L/6EA/36BOX/1PLT/용기(플라스틱) | E38: =VLOOKUP(B38,푸디스트!A:D,4,FALSE) -> 3020 | H38: =VLOOKUP(F38,현그푸!A:D,3,FALSE) -> #N/A | I38: =VLOOKUP(F38,현그푸!A:D,4,FALSE) -> #N/A
A39: 오리고기(살코기) | D39: =VLOOKUP(B39,푸디스트!A:D,3,FALSE) -> #N/A | E39: =VLOOKUP(B39,푸디스트!A:D,4,FALSE) -> #N/A | F39: 1325050 | G39: 오리(절단육,냉장,토막,국산) | H39: =VLOOKUP(F39,현그푸!A:D,3,FALSE) -> 1Kg(100~120g) | I39: =VLOOKUP(F39,현그푸!A:D,4,FALSE) -> 14030
A40: 육수 | B40: F127421 | C40: 진육수(대상) | D40: =VLOOKUP(B40,푸디스트!A:D,3,FALSE) -> 960G | E40: =VLOOKUP(B40,푸디스트!A:D,4,FALSE) -> 11990 | H40: =VLOOKUP(F40,현그푸!A:D,3,FALSE) -> #N/A | I40: =VLOOKUP(F40,현그푸!A:D,4,FALSE) -> #N/A
...

Sheet 상세결과
A1: 식재료 | B1: 푸디스트_선택 | C1: 푸디스트_코드 | D1: 현그푸_선택 | E1: 현그푸_코드 | F1: 푸디스트_1순위 | G1: 현그푸_1순위
A2: 북어채 | B2: 북어채(러시아산) | C2: F106193 | D2: 북어채(중국가공)(상품,냉장,러시아) | E2: 1248326 | F2: 북어채(러시아산) | G2: 북어채(중국가공)(상품,냉장,러시아)
A3: 기타 즉석식품_찐고구마 | B3: 브리또 고구마치즈(남향) | C3: F260781 | D3: (C)고구마(상품,냉장,튀김용,채썰기,국산) | E3: 1327654 | F3: 브리또 고구마치즈(남향) | G3: 고구마(상품,실온,친환경,국산)
A4: 햄치즈샌드위치 | B4: 햄치즈샌드(복음자리) | C4: F346322 | D4: [H-간편식]햄치즈샌드위치(스마트푸드센터,냉장) | E4: 1856236 | F4: 햄치즈샌드(복음자리) | G4: [H-간편식]햄치즈샌드위치(스마트푸드센터,냉장)
A5: 열무김치 | B5: 열무김치(국내산/풍미)생 | C5: F110395 | D5: 열무김치(선농식품,실온,초숙,국산) | E5: 1365299 | F5: 열무김치(국내산/풍미)생 | G5: 열무김치(선농식품,실온,초숙,국산)
A6: 계란(구운것) | B6: 계란(왕란/국내산/무항생제) | C6: F339652 | D6: 계란(대란)(냉장,세척,국산) | E6: 1242194 | F6: 계란(왕란/국내산/무항생제) | G6: 계란(대란)(냉장,세척,국산)
A7: 고구마줄기 | B7: 고구마떡(엄지식품) | C7: F335868 | D7: (C)고구마(상품,냉장,튀김용,채썰기,국산) | E7: 1327654 | F7: 고구마떡(엄지식품) | G7: 고구마(상품,실온,친환경,국산)
A8: 쇠고기(구이용) | B8: 쇠고기죽(동원) | C8: F127548 | D8: 쇠고기맛나(대상,실온) | E8: 1258011 | F8: 쇠고기죽(동원) | G8: 쇠고기맛나(대상,실온)
A9: 김자반(시판) | B9: 돌김자반(태산) | C9: F355348 | D9: 김(상품,김밥용,국산) | E9: 1331443 | F9: 돌김자반(태산) | G9: 김(상품,김밥용,국산)
A10: 시금치(냉동) | B10: 시금치(국내산) | C10: F100756 | D10: 시금치(상품,실온,국산) | E10: 1242356 | F10: 시금치(국내산) | G10: 시금치(상품,실온,국산)
A11: 근대(냉동) | B11: 냉동근대(중국산) | C11: F323702 | D11: 근대(상품,실온,국산) | E11: 1242294 | F11: 냉동근대(중국산) | G11: 근대(상품,실온,국산)
A12: 굴 | B12: (식자재왕)전복넣은_굴소스_2.2kg | C12: F343568 | D12: 굴(유성수산,냉동,국산) | E12: 1830117 | F12: (식자재왕)전복넣은_굴소스_2.2kg | G12: 굴(유성수산,냉동,국산)
A13: 방울토마토 | B13: 방울토마토(중/3번과/국내산)KG | C13: F102212 | D13: 방울토마토(특품,실온,국산) | E13: 1245520 | F13: 방울토마토(중/3번과/국내산)KG | G13: 방울토마토(특품,실온,국산)
... A146: 소금 | B146: 맛소금(대상) | C146: F118737 | D146: 소금(말돈)(상온,영국) | E146: 1494641 | F146: 맛소금(대상) | G146: 소금(말돈)(상온,영국)

Sheet 푸디스트
A1: 상품코드 | B1: 상품명 | C1: 규격 | D1: 단가
A2: F297908 | B2: (식자재왕)미니족발_600g | C2: 600g/20 | D2: 5090
A3: F297993 | B3: (식자재왕)햄야채볶음밥280g | C3: 280g/25 | D3: 1030
A4: F298001 | B4: (식자재왕)야채볶음밥_벌크3kg | C4: 3kg/3 | D4: 10050
A5: F298003 | B5: (식자재왕)소불고기볶음밥280g | C5: 280g/25 | D5: 1370
A6: F298004 | B6: (식자재왕)새우볶음밥280g | C6: 280g/25 | D6: 1300
A7: F298005 | B7: (식자재왕)불닭소스2.3kg | C7: 2.3kg/6 | D7: 8500
A8: F298012 | B8: (식자재왕)낙지볶음밥280g | C8: 280g/25 | D8: 1320
A9: F298019 | B9: (식자재왕)김치볶음밥280g | C9: 280g/25 | D9: 1290
A10: F298027 | B10: (식자재왕)계란야채볶음밥280g | C10: 280g/25 | D10: 960
A11: F298124 | B11: (식자재왕)미트볼1.5kg | C11: 1.5kg/6(11.5g*130) | D11: 5880
A12: F298133 | B12: (식자재왕)모밀쯔유1.75L | C12: 1.75L/6 | D12: 7580
A13: F298146 | B13: (식자재왕)메밀전병_120g*10_1.2kg | C13: 1.2kg/8 | D13: 6830
... A1995: F112935 | B1995: 냉동생와사비(303/승진) | C1995: 750g/팩(스파우트)/우리승진식품 | D1995: 11220
A1996: F112952 | B1996: 메가크런치(심플로트) | D1996: 12340
A1997: F112956 | B1997: 비취교(골든피트) | C1997: 360G(18G×20EA) | D1997: 4300
A1998: F112957 | B1998: 해물샤오마이(골든피트) | C1998: 15G*24EA/골든피트 | D1998: 5790
A1999: F113078 | B1999: 유부(CJ씨푸드) | C1999: 300G/냉동 | D1999: 3990
A2000: F113081 | B2000: 선냉동유부(대림) | C2000: 6.4gx80개입/한미식품 | D2000: 5060
A2001: F113085 | B2001: 주부초밥(CJ씨푸드) | C2001: 640G/냉장 | D2001: 6470
A2002: F113087 | B2002: [WB]유부(사조대림_주부초밥짱)480g | C2002: 480G(12G*42내외)/한미식품 | D2002: 3980
A2003: F113101 | B2003: 냉동유부슬라이스(CJ씨푸드) | C2003: 1KG/냉동/신미 | D2003: 11440
A2004: F113264 | B2004: 맛있는우유GT/200㎖(남양) | C2004: 200㎖/D-1 16시 | D2004: 560
A2005: F113649 | B2005: 파마산치즈가루(칸) | C2005: 1KG/분말/우전산업 | D2005: 11760
A2006: F113663 | B2006: 5P스위스치즈(데어리) | C2006: 2.27KG(19G*120개입)/미국산/기타 치즈류 | D2006: 38780
A2007: F113699 | B2007: 체다슬라이스치즈(썬리취) | C2007: 18G*100매/썬리취 | D2007: 18340
A2008: F113705 | B2008: 파마산치즈(삼조) | C2008: 1KG | D2008: 14180
... A4952: F250378 | B4952: 롯데쿡전통소시지(롯데푸드) | C4952: 1KG/EA | D4952: 3750
A4953: F250391 | B4953: 냉동생와사비705(페이스트/움트리) | D4953: 14430
A4954: F250475 | B4954: 우유튀김(사옹원) | C4954: 1KG(19G*53EA) | D4954: 11750
A4955: F250560 | B4955: 노리후리가케(식예원 또는 김맛) | C4955: 50G/개별포장 | D4955: 770
A4956: F250598 | B4956: 피자치즈DMC1(코다노) | C4956: 2.5KG/자연치즈(모짜)20%,모조치즈80% | D4956: 20330
A4957: F250625 | B4957: 동태(러시아산) | C4957: 냉동/EA/원물/400~600g/미 | D4957: 3810
A4958: F250768 | B4958: 냉동누드은행(이엔푸드)500g | C4958: 500G | D4958: 4370
A4959: F250788 | B4959: [WB]찐만두(아하_김치_28g*50ea)1.4kg | C4959: 1.4KG(28G*50EA내외) | D4959: 7070
A4960: F250789 | B4960: [WB]찐만두(아하_고기_28g*50ea)1.4kg | C4960: 1.4KG(28G*50EA내외) | D4960: 6970
A4961: F250810 | B4961: 양념소금(순대소금,일회용) | C4961: 3G*200EA | D4961: 4290
A4962: F250828 | B4962: 애플파이(딤섬) | C4962: 450G(15G*30EA) | D4962: 2500
A4963: F250839 | B4963: [WB]골드함박스테이크(삼양) | C4963: 1KG(100G*10개입) | D4963: 5320
A4964: F250840 | B4964: [WB]임꺽정떡갈비1.4KG(삼양) | C4964: 1.4KG(140G*10EA) | D4964: 11280
...

Sheet 현그푸
A1: 단품코드 | B1: 단품명 | C1: 규격 | D1: 세포함단가
A2: 1244474 | B2: (C)양상추(상품,실온,겉잎제거,국산) | C2: 1Kg(300~500g/통) | D2: 6080
A3: 1873723 | B3: (C)양상추(상품,냉장,나박썰기,국산) | C3: 1Kg(4*5cm) | D3: 6470
A4: 1243846 | B4: 양배추(실온,겉잎제거,국산) | C4: 1Kg | D4: 2210
A5: 1244322 | B5: (지속)양배추(상품,실온,친환경,국산) | C5: 2Kg | D5: 10480
A6: 1244431 | B6: (C)양배추(상품,실온,겉잎제거,중국) | C6: 1Kg(1.5~2.5Kg/통당) | D6: 1190
A7: 1244452 | B7: 깐양배추(상품,실온,주스용,국산) | C7: 1Kg(1.5~2.5Kg/통당) | D7: 1980
A8: 1244588 | B8: (C)양배추(상품,냉장,채썰기,국산) | C8: 1Kg(4mm/채썰기) | D8: 3430
A9: 1327729 | B9: (C)양배추(상품,사각,볶음조림용)(실온,국산) | C9: 1Kg(20*30mm) | D9: 3430
A10: 1327739 | B10: (C)양배추(채,샐러드,비빔밥용)(냉장,국산) | C10: 1Kg(2mm내외) | D10: 3320
A11: 1341776 | B11: 방울양배추(상품,수입) | C11: 1Kg(500g(2봉)) | D11: 23390
A12: 1346074 | B12: 양배추(상품,실온,국산) | C12: 1Kg | D12: 1610
A13: 1390105 | B13: (C)양배추(상품,냉장,샐러드용,채썰기,국산) | C13: 1Kg(1mm/채썰기) | D13: 3320
... A2366: 1308511 | B2366: 돈육(등갈비,냉동,찜용,국산) | C2366: 1Kg(갈비대 1pcs절단) | D2366: 24770
A2367: 1372240 | B2367: 돈육(등갈비,통덩어리,냉동,프랑스) | D2367: 16150
A2368: 1382320 | B2368: 돈육(등갈비,냉동,찜용,스페인) | C2368: 1Kg(뼈사이절단, 한대씩 반커팅) | D2368: 14810
A2369: 1403983 | B2369: 돈육(LA갈비,냉장,국산) | C2369: 1Kg(4*3*1cm) | D2369: 16060
A2370: 1407059 | B2370: 돈육(등갈비,냉동,찜용,스페인) | C2370: 1Kg(뼈사이절단) | D2370: 14500
A2371: 1412102 | B2371: [H-Kids]돈육(갈비,1등급,냉장,찜용,국산) | C2371: 1Kg(4*4*3cm/트레이포장) | D2371: 27120
A2372: 1479079 | B2372: 돈육(등갈비,냉동,찜용,국산) | C2372: 1Kg(한대씩 절단, 뼈길이 7cm) | D2372: 24770
A2373: 1542269 | B2373: (A)돈육(등갈비,냉장,국산) | C2373: 1Kg(전용코드, 원물채출고) | D2373: 33520
A2374: 1549108 | B2374: (소량전용)돈육(등갈비,냉장,통덩어리,국산) | C2374: Kg(1kg미만발주가능) | D2374: 32120
A2375: 1549109 | B2375: (소량전용)돈육(등갈비,냉장,찜용,국산) | C2375: 갈비대 1~2pcs로 절단, 30~60g(1kg미만발주가능) | D2375: 32120
A2376: 1549589 | B2376: (소량전용)돈육(갈비,냉동,찜용,미국) | C2376: 1Kg(2.5*2.5*2.5cm/1kg미만발주가능) | D2376: 16980
A2377: 1549591 | B2377: (소량전용)돈육(등갈비,냉동,찜용,스페인) | C2377: 1Kg(뼈사이절단, 1kg미만발주가능) | D2377: 15890
A2378: 1252725 | B2378: 돈육(안심,냉장,국산) | C2378: 1Kg(75g/덩어리) | D2378: 15790
A2379: 1407188 | B2379: [H-Kids]돈육(안심,냉장,통덩어리,무항생제,국산) | C2379: 1Kg(트레이포장) | D2379: 22760
... A3649: 1394772 | B3649: 우육(토시살,냉동,찹스테이크용,호주) | C3649: 1Kg(2.5*2.5*2.5cm) | D3649: 19180
A3650: 1394773 | B3650: 우육(토시살,통덩어리,냉동,호주) | D3650: 18710
A3651: 1453222 | B3651: 우육(토시살,냉동,찹스테이크용,호주) | C3651: 1Kg(2.5*2.5*1cm) | D3651: 19180
A3652: 1461916 | B3652: 우육(토시살,냉동,찹스테이크용,호주) | C3652: 1Kg(3*3*1.5cm) | D3652: 19180
A3653: 1522664 | B3653: 우육(토시살,냉동,슬라이스,호주) | C3653: 3mm슬라이스(짜투리포함) | D3653: 19490
A3654: 1529736 | B3654: 우육(토시살,냉동,찹스테이크용,호주) | C3654: 1Kg(2*2*2cm) | D3654: 19180
A3655: 1549557 | B3655: (소량전용)우육(토시살,냉동,찹스테이크용,호주) | C3655: 1Kg(2.5*2.5*2.5cm/1kg미만발주가능) | D3655: 20570
A3656: 1549558 | B3656: (소량전용)우육(토시살,냉동,통덩어리,호주) | C3656: 1Kg(1kg미만발주가능) | D3656: 20100
A3657: 1254752 | B3657: 우육(설깃,냉동,통덩어리,호주) | C3657: 5Kg(실중량변경) | D3657: 105980
A3658: 1475671 | B3658: 우육(설깃,냉동,Choice,슬라이스,미국) | C3658: 0.3cm슬라이스/kg | D3658: 24160
A3659: 1475673 | B3659: 우육(설깃,냉동,Choice,국용,미국)(설깃,냉동,Choice,국용,미국) | C3659: 1Kg(3*4*0.3cm) | D3659: 24160
A3660: 1254243 | B3660: 육우(냉동,통덩어리,국산) | C3660: 1Kg | D3660: 30400
A3661: 1254389 | B3661: 우육(정육,냉동,Choice,불고기용,미국) | C3661: 7*7*0.1 | D3661: 27180
...
